<?xml version='1.0' encoding='utf-8'?>
<robot name="panda">
  <material name="Vis">
    <color rgba="0.0 0.0 0.0 0.0" />
  </material>
  <link name="panda_link0">
    <visual>
      <geometry>
        <mesh filename="package://meshes/libero_obj_visual/link0_vis/link0_vis_0.obj" />
      </geometry>
    </visual>
    <visual>
      <geometry>
        <mesh filename="package://meshes/libero_obj_visual/link0_vis/link0_vis_1.obj" />
      </geometry>
    </visual>
    <visual>
      <geometry>
        <mesh filename="package://meshes/libero_obj_visual/link0_vis/link0_vis_2.obj" />
      </geometry>
    </visual>
    <visual>
      <geometry>
        <mesh filename="package://meshes/libero_obj_visual/link0_vis/link0_vis_3.obj" />
      </geometry>
    </visual>
    <visual>
      <geometry>
        <mesh filename="package://meshes/libero_obj_visual/link0_vis/link0_vis_4.obj" />
      </geometry>
    </visual>
    <visual>
      <geometry>
        <mesh filename="package://meshes/libero_obj_visual/link0_vis/link0_vis_5.obj" />
      </geometry>
    </visual>
    <visual>
      <geometry>
        <mesh filename="package://meshes/libero_obj_visual/link0_vis/link0_vis_6.obj" />
      </geometry>
    </visual>
    <visual>
      <geometry>
        <mesh filename="package://meshes/libero_obj_visual/link0_vis/link0_vis_7.obj" />
      </geometry>
    </visual>
    <visual>
      <geometry>
        <mesh filename="package://meshes/libero_obj_visual/link0_vis/link0_vis_8.obj" />
      </geometry>
    </visual>
    <visual>
      <geometry>
        <mesh filename="package://meshes/libero_obj_visual/link0_vis/link0_vis_9.obj" />
      </geometry>
    </visual>
    <visual>
      <geometry>
        <mesh filename="package://meshes/libero_obj_visual/link0_vis/link0_vis_10.obj" />
      </geometry>
    </visual>
    <visual>
      <geometry>
        <mesh filename="package://meshes/libero_obj_visual/link0_vis/link0_vis_11.obj" />
      </geometry>
    </visual>
    <collision>
      <geometry>
        <mesh filename="package://meshes/collision/link0.obj" />
      </geometry>
    </collision>
  </link>
  <link name="panda_link1">
    <visual>
      <geometry>
        <mesh filename="package://meshes/libero_obj_visual/link1_vis/link1_vis.obj" />
      </geometry>
    </visual>
    <collision>
      <geometry>
        <mesh filename="package://meshes/collision/link1.obj" />
      </geometry>
    </collision>
  </link>
  <joint name="panda_joint1" type="revolute">
    <safety_controller k_position="100.0" k_velocity="40.0" soft_lower_limit="-2.8973" soft_upper_limit="2.8973" />
    <origin rpy="0 0 0" xyz="0 0 0.333" />
    <parent link="panda_link0" />
    <child link="panda_link1" />
    <axis xyz="0 0 1" />
    <dynamics damping="10.0" />
    <limit effort="87" lower="-2.8973" upper="2.8973" velocity="2.1750" />
  </joint>
  <link name="panda_link2">
    <visual>
      <geometry>
        <mesh filename="package://meshes/libero_obj_visual/link2_vis/link2_vis.obj" />
      </geometry>
    </visual>
    <collision>
      <geometry>
        <mesh filename="package://meshes/collision/link2.obj" />
      </geometry>
    </collision>
  </link>
  <joint name="panda_joint2" type="revolute">
    <safety_controller k_position="100.0" k_velocity="40.0" soft_lower_limit="-1.7628" soft_upper_limit="1.7628" />
    <origin rpy="-1.57079632679 0 0" xyz="0 0 0" />
    <parent link="panda_link1" />
    <child link="panda_link2" />
    <axis xyz="0 0 1" />
    <dynamics damping="10.0" />
    <limit effort="87" lower="-1.7628" upper="1.7628" velocity="2.1750" />
  </joint>
  <link name="panda_link3">
    <visual>
      <geometry>
        <mesh filename="package://meshes/libero_obj_visual/link3_vis/link3_vis_0.obj" />
      </geometry>
    </visual>
    <visual>
      <geometry>
        <mesh filename="package://meshes/libero_obj_visual/link3_vis/link3_vis_1.obj" />
      </geometry>
    </visual>
    <visual>
      <geometry>
        <mesh filename="package://meshes/libero_obj_visual/link3_vis/link3_vis_2.obj" />
      </geometry>
    </visual>
    <visual>
      <geometry>
        <mesh filename="package://meshes/libero_obj_visual/link3_vis/link3_vis_3.obj" />
      </geometry>
    </visual>
    <collision>
      <geometry>
        <mesh filename="package://meshes/collision/link3.obj" />
      </geometry>
    </collision>
  </link>
  <joint name="panda_joint3" type="revolute">
    <safety_controller k_position="100.0" k_velocity="40.0" soft_lower_limit="-2.8973" soft_upper_limit="2.8973" />
    <origin rpy="1.57079632679 0 0" xyz="0 -0.316 0" />
    <parent link="panda_link2" />
    <child link="panda_link3" />
    <axis xyz="0 0 1" />
    <dynamics damping="10.0" />
    <limit effort="87" lower="-2.8973" upper="2.8973" velocity="2.1750" />
  </joint>
  <link name="panda_link4">
    <visual>
      <geometry>
        <mesh filename="package://meshes/libero_obj_visual/link4_vis/link4_vis_0.obj" />
      </geometry>
    </visual>
    <visual>
      <geometry>
        <mesh filename="package://meshes/libero_obj_visual/link4_vis/link4_vis_1.obj" />
      </geometry>
    </visual>
    <visual>
      <geometry>
        <mesh filename="package://meshes/libero_obj_visual/link4_vis/link4_vis_2.obj" />
      </geometry>
    </visual>
    <visual>
      <geometry>
        <mesh filename="package://meshes/libero_obj_visual/link4_vis/link4_vis_3.obj" />
      </geometry>
    </visual>
    <collision>
      <geometry>
        <mesh filename="package://meshes/collision/link4.obj" />
      </geometry>
    </collision>
  </link>
  <joint name="panda_joint4" type="revolute">
    <safety_controller k_position="100.0" k_velocity="40.0" soft_lower_limit="-3.0718" soft_upper_limit="-0.0698" />
    <origin rpy="1.57079632679 0 0" xyz="0.0825 0 0" />
    <parent link="panda_link3" />
    <child link="panda_link4" />
    <axis xyz="0 0 1" />
    <dynamics damping="10.0" />
    <limit effort="87" lower="-3.0718" upper="-0.0698" velocity="2.1750" />
  </joint>
  <link name="panda_link5">
    <visual>
      <geometry>
        <mesh filename="package://meshes/libero_obj_visual/link5_vis/link5_vis_0.obj" />
      </geometry>
    </visual>
    <visual>
      <geometry>
        <mesh filename="package://meshes/libero_obj_visual/link5_vis/link5_vis_1.obj" />
      </geometry>
    </visual>
    <visual>
      <geometry>
        <mesh filename="package://meshes/libero_obj_visual/link5_vis/link5_vis_2.obj" />
      </geometry>
    </visual>
    <collision>
      <geometry>
        <mesh filename="package://meshes/collision/link5.obj" />
      </geometry>
    </collision>
  </link>
  <joint name="panda_joint5" type="revolute">
    <safety_controller k_position="100.0" k_velocity="40.0" soft_lower_limit="-2.8973" soft_upper_limit="2.8973" />
    <origin rpy="-1.57079632679 0 0" xyz="-0.0825 0.384 0" />
    <parent link="panda_link4" />
    <child link="panda_link5" />
    <axis xyz="0 0 1" />
    <dynamics damping="10.0" />
    <limit effort="12" lower="-2.8973" upper="2.8973" velocity="2.6100" />
  </joint>
  <link name="panda_link6">
    <visual>
      <geometry>
        <mesh filename="package://meshes/libero_obj_visual/link6_vis/link6_vis_0.obj" />
      </geometry>
    </visual>
    <visual>
      <geometry>
        <mesh filename="package://meshes/libero_obj_visual/link6_vis/link6_vis_1.obj" />
      </geometry>
    </visual>
    <visual>
      <geometry>
        <mesh filename="package://meshes/libero_obj_visual/link6_vis/link6_vis_2.obj" />
      </geometry>
    </visual>
    <visual>
      <geometry>
        <mesh filename="package://meshes/libero_obj_visual/link6_vis/link6_vis_3.obj" />
      </geometry>
    </visual>
    <visual>
      <geometry>
        <mesh filename="package://meshes/libero_obj_visual/link6_vis/link6_vis_4.obj" />
      </geometry>
    </visual>
    <visual>
      <geometry>
        <mesh filename="package://meshes/libero_obj_visual/link6_vis/link6_vis_5.obj" />
      </geometry>
    </visual>
    <visual>
      <geometry>
        <mesh filename="package://meshes/libero_obj_visual/link6_vis/link6_vis_6.obj" />
      </geometry>
    </visual>
    <visual>
      <geometry>
        <mesh filename="package://meshes/libero_obj_visual/link6_vis/link6_vis_7.obj" />
      </geometry>
    </visual>
    <visual>
      <geometry>
        <mesh filename="package://meshes/libero_obj_visual/link6_vis/link6_vis_8.obj" />
      </geometry>
    </visual>
    <visual>
      <geometry>
        <mesh filename="package://meshes/libero_obj_visual/link6_vis/link6_vis_9.obj" />
      </geometry>
    </visual>
    <visual>
      <geometry>
        <mesh filename="package://meshes/libero_obj_visual/link6_vis/link6_vis_10.obj" />
      </geometry>
    </visual>
    <visual>
      <geometry>
        <mesh filename="package://meshes/libero_obj_visual/link6_vis/link6_vis_11.obj" />
      </geometry>
    </visual>
    <visual>
      <geometry>
        <mesh filename="package://meshes/libero_obj_visual/link6_vis/link6_vis_12.obj" />
      </geometry>
    </visual>
    <visual>
      <geometry>
        <mesh filename="package://meshes/libero_obj_visual/link6_vis/link6_vis_13.obj" />
      </geometry>
    </visual>
    <visual>
      <geometry>
        <mesh filename="package://meshes/libero_obj_visual/link6_vis/link6_vis_14.obj" />
      </geometry>
    </visual>
    <visual>
      <geometry>
        <mesh filename="package://meshes/libero_obj_visual/link6_vis/link6_vis_15.obj" />
      </geometry>
    </visual>
    <visual>
      <geometry>
        <mesh filename="package://meshes/libero_obj_visual/link6_vis/link6_vis_16.obj" />
      </geometry>
    </visual>
    <collision>
      <geometry>
        <mesh filename="package://meshes/collision/link6.obj" />
      </geometry>
    </collision>
  </link>
  <joint name="panda_joint6" type="revolute">
    <safety_controller k_position="100.0" k_velocity="40.0" soft_lower_limit="-0.0175" soft_upper_limit="3.7525" />
    <origin rpy="1.57079632679 0 0" xyz="0 0 0" />
    <parent link="panda_link5" />
    <child link="panda_link6" />
    <axis xyz="0 0 1" />
    <dynamics damping="10.0" />
    <limit effort="12" lower="-0.0175" upper="3.7525" velocity="2.6100" />
  </joint>
  <link name="panda_link7">
    <visual>
      <geometry>
        <mesh filename="package://meshes/libero_obj_visual/link7_vis/link7_vis_0.obj" />
      </geometry>
    </visual>
    <visual>
      <geometry>
        <mesh filename="package://meshes/libero_obj_visual/link7_vis/link7_vis_1.obj" />
      </geometry>
    </visual>
    <visual>
      <geometry>
        <mesh filename="package://meshes/libero_obj_visual/link7_vis/link7_vis_2.obj" />
      </geometry>
    </visual>
    <visual>
      <geometry>
        <mesh filename="package://meshes/libero_obj_visual/link7_vis/link7_vis_3.obj" />
      </geometry>
    </visual>
    <visual>
      <geometry>
        <mesh filename="package://meshes/libero_obj_visual/link7_vis/link7_vis_4.obj" />
      </geometry>
    </visual>
    <visual>
      <geometry>
        <mesh filename="package://meshes/libero_obj_visual/link7_vis/link7_vis_5.obj" />
      </geometry>
    </visual>
    <visual>
      <geometry>
        <mesh filename="package://meshes/libero_obj_visual/link7_vis/link7_vis_6.obj" />
      </geometry>
    </visual>
    <visual>
      <geometry>
        <mesh filename="package://meshes/libero_obj_visual/link7_vis/link7_vis_7.obj" />
      </geometry>
    </visual>
    <collision>
      <geometry>
        <mesh filename="package://meshes/collision/link7.obj" />
      </geometry>
    </collision>
  </link>
  <joint name="panda_joint7" type="revolute">
    <safety_controller k_position="100.0" k_velocity="40.0" soft_lower_limit="-2.8973" soft_upper_limit="2.8973" />
    <origin rpy="1.57079632679 0 0" xyz="0.088 0 0" />
    <parent link="panda_link6" />
    <child link="panda_link7" />
    <axis xyz="0 0 1" />
    <dynamics damping="10.0" />
    <limit effort="12" lower="-2.8973" upper="2.8973" velocity="2.6100" />
  </joint>
  <joint name="panda_hand_joint" type="fixed">
    <parent link="panda_link7" />
    <child link="panda_hand" />
    <origin rpy="0 0 -0.785398163397" xyz="0 0 0.107" />
  </joint>
  <link name="panda_hand">
    <visual>
      <geometry>
        <mesh filename="package://meshes/libero_obj_visual/hand.obj" />
      </geometry>
    </visual>
    <collision>
      <geometry>
        <mesh filename="package://meshes/collision/hand.obj" />
      </geometry>
    </collision>
  </link>
  <link name="panda_leftfinger">
    <visual>
      <geometry>
        <mesh filename="package://meshes/libero_obj_visual/finger.obj" />
      </geometry>
    </visual>
    <collision>
      <geometry>
        <mesh filename="package://meshes/collision/finger.obj" />
      </geometry>
    </collision>
  </link>
  <link name="panda_rightfinger">
    <visual>
      <origin rpy="0 0 3.14159265359" xyz="0 0 0" />
      <geometry>
        <mesh filename="package://meshes/libero_obj_visual/finger.obj" />
      </geometry>
    </visual>
    <collision>
      <origin rpy="0 0 3.14159265359" xyz="0 0 0" />
      <geometry>
        <mesh filename="package://meshes/collision/finger.obj" />
      </geometry>
    </collision>
  </link>
  <joint name="panda_finger_joint1" type="prismatic">
    <parent link="panda_hand" />
    <child link="panda_leftfinger" />
    <origin rpy="0 0 0" xyz="0 0 0.0584" />
    <axis xyz="0 1 0" />
    <dynamics damping="10.0" />
    <limit effort="20" lower="0.0" upper="0.04" velocity="0.2" />
  </joint>
  <joint name="panda_finger_joint2" type="prismatic">
    <parent link="panda_hand" />
    <child link="panda_rightfinger" />
    <origin rpy="0 0 0" xyz="0 0 0.0584" />
    <axis xyz="0 -1 0" />
    <dynamics damping="10.0" />
    <limit effort="20" lower="0.0" upper="0.04" velocity="0.2" />
    <mimic joint="panda_finger_joint1" />
  </joint>
  <joint name="panda_grip_vis_joint" type="fixed">
    <parent link="panda_hand" />
    <child link="panda_grip_site" />
    <origin rpy="0 0 0" xyz="0 0 0.1025" />
  </joint>
  <link name="panda_grip_site">
    
  </link>
  <joint name="panda_leftfinger_tip_joint" type="fixed">
    <parent link="panda_leftfinger" />
    <child link="panda_leftfinger_tip" />
    <origin rpy="0 0 0" xyz="0.0 0.0015 0.0441" />
  </joint>
  <link name="panda_leftfinger_tip">
    <collision>
      <geometry>
        <box size="0.013 0.004 0.013" />
      </geometry>
    </collision>
  </link>
  <joint name="panda_rightfinger_tip_joint" type="fixed">
    <parent link="panda_rightfinger" />
    <child link="panda_rightfinger_tip" />
    <origin rpy="0 0 0" xyz="0.0 -0.0015 0.0441" />
  </joint>
  <link name="panda_rightfinger_tip">
    <collision>
      <geometry>
        <box size="0.013 0.004 0.013" />
      </geometry>
    </collision>
  </link>
  <link name="wrist_camera_link">
    <inertial>
      <origin xyz="0 0 0" rpy="0 0 0" />
      <mass value="0.01" />
      <inertia ixx="1e-6" ixy="0" ixz="0" iyy="1e-6" iyz="0" izz="1e-6" />
    </inertial>
    <visual>
      <origin xyz="0 0 0" rpy="0 0 0" />
      <geometry>
        <box size="0.03 0.03 0.01" />
      </geometry>
      <material name="dark_grey">
        <color rgba="0.2 0.2 0.2 1.0" />
      </material>
    </visual>
  </link>
  <joint name="wrist_camera_mount" type="fixed">
    <parent link="panda_hand" />
    <child link="wrist_camera_link" />
    <origin xyz="0.05 0.0 0.0" rpy="0 0 1.57079632679" />
  </joint>
</robot>